2020/10/16 00:47:37 logger.go:297: Attempt 1 of http call to http://10.0.0.8:16384/sendlogstoartifacts/info
2020/10/16 00:47:38 logger.go:297: Attempt 1 of http call to http://10.0.0.8:16384/sendlogstoartifacts/status
[2020-10-16T00:47:39.175595] Entering context manager injector.
[context_manager_injector.py] Command line Options: Namespace(inject=['ProjectPythonPath:context_managers.ProjectPythonPath', 'RunHistory:context_managers.RunHistory', 'TrackUserError:context_managers.TrackUserError'], invocation=['train.py', '--C', '0.1', '--penalty', 'l2'])
Starting the daemon thread to refresh tokens in background for process with pid = 108
Entering Run History Context Manager.
Current directory:  /mnt/batch/tasks/shared/LS_root/jobs/quick-starts-ws-120897/azureml/hd_6c323588-af9e-4d1b-acb2-64b3db1c81c3_1/mounts/workspaceblobstore/azureml/HD_6c323588-af9e-4d1b-acb2-64b3db1c81c3_1
Preparing to call script [ train.py ] with arguments: ['--C', '0.1', '--penalty', 'l2']
After variable expansion, calling script [ train.py ] with arguments: ['--C', '0.1', '--penalty', 'l2']

Script type = None
Starting the daemon thread to refresh tokens in background for process with pid = 108


[2020-10-16T00:47:41.561431] The experiment failed. Finalizing run...
[2020-10-16T00:47:41.561471] FinalizingInRunHistory is not called
Cleaning up all outstanding Run operations, waiting 300.0 seconds
1 items cleaning up...
Cleanup took 0.07987380027770996 seconds
Traceback (most recent call last):
  File "/mnt/batch/tasks/shared/LS_root/jobs/quick-starts-ws-120897/azureml/hd_6c323588-af9e-4d1b-acb2-64b3db1c81c3_1/mounts/workspaceblobstore/azureml/HD_6c323588-af9e-4d1b-acb2-64b3db1c81c3_1/azureml-setup/context_manager_injector.py", line 311, in <module>
    execute_with_context(cm_objects, options.invocation)
  File "/mnt/batch/tasks/shared/LS_root/jobs/quick-starts-ws-120897/azureml/hd_6c323588-af9e-4d1b-acb2-64b3db1c81c3_1/mounts/workspaceblobstore/azureml/HD_6c323588-af9e-4d1b-acb2-64b3db1c81c3_1/azureml-setup/context_manager_injector.py", line 166, in execute_with_context
    runpy.run_path(sys.argv[0], globals(), run_name="__main__")
  File "/opt/miniconda/lib/python3.6/runpy.py", line 261, in run_path
    code, fname = _get_code_from_file(run_name, path_name)
  File "/opt/miniconda/lib/python3.6/runpy.py", line 231, in _get_code_from_file
    with open(fname, "rb") as f:
FileNotFoundError: [Errno 2] No such file or directory: 'train.py'

[2020-10-16T00:47:42.101542] Finished context manager injector with Exception.
2020/10/16 00:47:42 logger.go:297: Failed to run the wrapper cmd with err: exit status 1
2020/10/16 00:47:42 logger.go:297: Attempt 1 of http call to http://10.0.0.8:16384/sendlogstoartifacts/status
2020/10/16 00:47:42 sysutils_linux.go:221: mpirun version string: {
Intel(R) MPI Library for Linux* OS, Version 2018 Update 3 Build 20180411 (id: 18329)
Copyright 2003-2018 Intel Corporation.
}
2020/10/16 00:47:42 sysutils_linux.go:225: MPI publisher: intel ; version: 2018
2020/10/16 00:47:42 logger.go:297: Process Exiting with Code:  1
